<?xml version="1.0" ?>
<!-- =================================================================================== -->
<!-- |    This document was autogenerated by xacro from spotmicro.urdf.xacro           | -->
<!-- |    EDITING THIS FILE BY HAND IS NOT RECOMMENDED                                 | -->
<!-- =================================================================================== -->
<robot name="spotmicro_rviz">
  <material name="yellow">
    <color rgba="0.92 0.83 0.0 1"/>
  </material>
  <material name="black">
    <color rgba="0.1 0.1 0.1 1"/>
  </material>
  <material name="grey">
    <color rgba="0.6 0.6 0.6 1"/>
  </material>
  <!-- Params -->
  <!-- Macros -->
  <!-- Robot Body -->
  <link name="base_link">
    <visual>
      <geometry>
        <mesh filename="package://spotmicro_description/urdf/stl/mainbody.stl" scale="0.001 0.001 0.001"/>
      </geometry>
      <material name="black"/>
      <origin rpy="0 0 0" xyz="-0.042 -0.055 -0.010"/>
    </visual>
    <collision>
      <geometry>
        <box size="0.14 0.11 0.07"/>
      </geometry>
      <origin rpy="0 0 0" xyz="0 0 0"/>
    </collision>
    <inertial>
      <mass value="2.80"/>
      <inertia ixx="100" ixy="0" ixz="0" iyy="100" iyz="0" izz="100"/>
    </inertial>
  </link>
  <!-- Lidar Backpack -->
  <!-- <link name="lidar_link">
    <visual>
      <geometry>
        <mesh filename="package://spotmicro_description/urdf/stl/rplidar_main.STL" scale="0.001 0.001 0.001"/>
      </geometry>
      <material name="black"/> 
      <origin rpy="1.57075 0 0" xyz="${-lidar_length/2+0.015} ${lidar_width/2+0.007} 0"/>
    </visual>
    <collision>
      <geometry>
        <box size="${lidar_length} ${lidar_width} ${lidar_height}"/>
      </geometry>
      <origin rpy="0 0 0" xyz="0 0 0"/>
    </collision>
    <inertial>
      <mass value="0.50"/>
      <inertia ixx="100" ixy="0" ixz="0" iyy="100" iyz="0" izz="100" />
    </inertial>
  </link>
  <joint name="base_lidar" type="fixed">
    <parent link="base_link"/>
    <child link="lidar_link"/>
        <origin xyz="0 0 ${body_height/2}"/>
  </joint>   -->
  <link name="rear_link">
    <visual>
      <geometry>
        <mesh filename="package://spotmicro_description/urdf/stl/backpart.stl" scale="0.001 0.001 0.001"/>
      </geometry>
      <origin rpy="0 0 3.14159" xyz="0.04 0.055 -0.010"/>
      <material name="black"/>
    </visual>
    <collision>
      <geometry>
        <box size="0.04 0.11 0.07"/>
      </geometry>
      <origin rpy="0 0 0" xyz="0.135 0 0"/>
    </collision>
    <inertial>
      <mass value="0.20"/>
      <inertia ixx="100" ixy="0" ixz="0" iyy="100" iyz="0" izz="100"/>
    </inertial>
  </link>
  <joint name="base_rear" type="fixed">
    <parent link="base_link"/>
    <child link="rear_link"/>
  </joint>
  <link name="front_link">
    <visual>
      <geometry>
        <mesh filename="package://spotmicro_description/urdf/stl/frontpart.stl" scale="0.001 0.001 0.001"/>
      </geometry>
      <origin rpy="0 0 3.14159" xyz="0.040 0.055 -0.010"/>
      <material name="black"/>
    </visual>
    <collision>
      <geometry>
        <box size="0.058 0.11 0.07"/>
      </geometry>
      <origin rpy="0 0 0" xyz="-0.145 0 0"/>
    </collision>
    <inertial>
      <mass value="0.20"/>
      <inertia ixx="100" ixy="0" ixz="0" iyy="100" iyz="0" izz="100"/>
    </inertial>
  </link>
  <joint name="base_front" type="fixed">
    <parent link="base_link"/>
    <child link="front_link"/>
  </joint>
  <!-- create femurs -->
  <link name="FL_coxa_link">
    <visual>
      <geometry>
        <mesh filename="package://spotmicro_description/urdf/stl/lshoulder.stl" scale="0.001 0.001 0.001"/>
      </geometry>
      <origin rpy="0 0 3.14159" xyz="0.135 0.015 -0.01"/>
      <material name="black"/>
    </visual>
    <collision>
      <geometry>
        <box size="0.044 0.038 0.07"/>
      </geometry>
      <origin rpy="0 0 0" xyz="0 0 0"/>
    </collision>
    <inertial>
      <mass value="0.10"/>
      <inertia ixx="100" ixy="0" ixz="0" iyy="100" iyz="0" izz="100"/>
    </inertial>
  </link>
  <link name="FL_femur_link_cover">
    <visual>
      <geometry>
        <mesh filename="package://spotmicro_description/urdf/stl/larm_cover.stl" scale="0.001 0.001 0.001"/>
      </geometry>
      <origin rpy="0 -0.139 3.14159" xyz="0.130 -0.040 -0.025"/>
      <material name="black"/>
    </visual>
  </link>
  <link name="FL_femur_link">
    <visual>
      <geometry>
        <mesh filename="package://spotmicro_description/urdf/stl/larm.stl" scale="0.001 0.001 0.001"/>
      </geometry>
      <origin rpy="0 -0.139 3.14159" xyz="0.130 -0.040 -0.025"/>
      <material name="black"/>
      <!--        <geometry>
          <box size="0.028 0.036 ${femur_length}"/>
        </geometry>
        <origin rpy="0.0 0.0 0.0" xyz="0.0 0.0 -0.050"/>
        <material name="black"/>-->
    </visual>
    <collision>
      <origin rpy="0.0 0.0 0.0" xyz="0.0 0.0 -0.050"/>
      <geometry>
        <box size="0.028 0.036 0.1075"/>
      </geometry>
    </collision>
    <inertial>
      <mass value="0.15"/>
      <inertia ixx="1000" ixy="0" ixz="0" iyy="1000" iyz="0" izz="1000"/>
    </inertial>
  </link>
  <link name="FL_tibia_link">
    <visual>
      <geometry>
        <mesh filename="package://spotmicro_description/urdf/stl/lfoot.stl" scale="0.001 0.001 0.001"/>
      </geometry>
      <origin rpy="0 0 3.14159" xyz="0.120 -0.04 0.1"/>
      <material name="black"/>
    </visual>
    <collision>
      <geometry>
        <box size="0.026 0.020 0.13"/>
      </geometry>
      <origin rpy="0.0 0.0 0.0" xyz="0.0 0.0 -0.050"/>
    </collision>
    <inertial>
      <mass value="0.1"/>
      <inertia ixx="1000" ixy="0" ixz="0" iyy="1000" iyz="0" izz="1000"/>
    </inertial>
  </link>
  <link name="FL_toe_link">
    <visual>
      <geometry>
        <mesh filename="package://spotmicro_description/urdf/stl/foot.stl" scale="0.001 0.001 0.001"/>
      </geometry>
      <origin rpy="0 -0.40010 3.14159" xyz="0.00 0.01 0.015"/>
      <material name="black"/>
    </visual>
    <collision>
      <geometry>
        <sphere radius="0.02"/>
      </geometry>
      <origin rpy="0 0 0" xyz="0 0 0.02"/>
      <contact_coefficients mu="1.1"/>
    </collision>
    <inertial>
      <mass value="0.05"/>
      <inertia ixx="1000" ixy="0" ixz="0" iyy="1000" iyz="0" izz="1000"/>
    </inertial>
  </link>
  <joint name="FL_Coxa" type="revolute">
    <parent link="base_link"/>
    <child link="FL_coxa_link"/>
    <axis xyz="1 0 0"/>
    <origin rpy="0 0 0" xyz="0.093 0.039 0"/>
    <limit effort="1000.0" lower="-0.548" upper="0.548" velocity="0.7"/>
    <dynamics damping="0.0" friction="0.5"/>
  </joint>
  <joint name="FL_Femur" type="revolute">
    <parent link="FL_coxa_link"/>
    <child link="FL_femur_link"/>
    <axis xyz="0 1 0"/>
    <origin rpy="0 1.4308 0" xyz="0 0.055 0"/>
    <limit effort="1000.0" lower="-1.5708" upper="0.523599" velocity="0.5"/>
    <dynamics damping="0.0" friction="0.0"/>
  </joint>
  <joint name="FL_femur_cover_joint" type="fixed">
    <parent link="FL_femur_link"/>
    <child link="FL_femur_link_cover"/>
    <origin xyz="0 0 0"/>
  </joint>
  <joint name="FL_Tibia" type="revolute">
    <parent link="FL_femur_link"/>
    <child link="FL_tibia_link"/>
    <axis xyz="0 1 0"/>
    <origin rpy="0 3.28159 0" xyz="0 0 -0.1075"/>
    <limit effort="1000.0" lower="0" upper="3.14159" velocity="0.5"/>
    <dynamics damping="0.0" friction="0.5"/>
  </joint>
  <joint name="FL_toe" type="fixed">
    <parent link="FL_tibia_link"/>
    <child link="FL_toe_link"/>
    <origin xyz="0 0 -0.13"/>
  </joint>
  <link name="FR_coxa_link">
    <visual>
      <geometry>
        <mesh filename="package://spotmicro_description/urdf/stl/rshoulder.stl" scale="0.001 0.001 0.001"/>
      </geometry>
      <origin rpy="0 0 3.14159" xyz="0.135 0.095 -0.01"/>
      <material name="black"/>
    </visual>
    <collision>
      <geometry>
        <box size="0.044 0.038 0.07"/>
      </geometry>
      <origin rpy="0 0 0" xyz="0 0 0"/>
    </collision>
    <inertial>
      <mass value="0.10"/>
      <inertia ixx="100" ixy="0" ixz="0" iyy="100" iyz="0" izz="100"/>
    </inertial>
  </link>
  <link name="FR_femur_link_cover">
    <visual>
      <geometry>
        <mesh filename="package://spotmicro_description/urdf/stl/rarm_cover.stl" scale="0.001 0.001 0.001"/>
      </geometry>
      <origin rpy="0 -0.139 3.14159" xyz="0.130 0.15 -0.025"/>
      <material name="black"/>
    </visual>
  </link>
  <link name="FR_femur_link">
    <visual>
      <geometry>
        <mesh filename="package://spotmicro_description/urdf/stl/rarm.stl" scale="0.001 0.001 0.001"/>
      </geometry>
      <origin rpy="0 -0.139 3.14159" xyz="0.130 0.15 -0.025"/>
      <material name="black"/>
      <!--        <geometry>
          <box size="0.028 0.036 ${femur_length}"/>
        </geometry>
        <origin rpy="0.0 0.0 0.0" xyz="0.0 0.0 -0.050"/>
        <material name="black"/>-->
    </visual>
    <collision>
      <origin rpy="0.0 0.0 0.0" xyz="0.0 0.0 -0.050"/>
      <geometry>
        <box size="0.028 0.036 0.1075"/>
      </geometry>
    </collision>
    <inertial>
      <mass value="0.15"/>
      <inertia ixx="1000" ixy="0" ixz="0" iyy="1000" iyz="0" izz="1000"/>
    </inertial>
  </link>
  <link name="FR_tibia_link">
    <visual>
      <geometry>
        <mesh filename="package://spotmicro_description/urdf/stl/rfoot.stl" scale="0.001 0.001 0.001"/>
      </geometry>
      <origin rpy="0 0 3.14159" xyz="0.120 0.15 0.1"/>
      <material name="black"/>
    </visual>
    <collision>
      <geometry>
        <box size="0.026 0.020 0.13"/>
      </geometry>
      <origin rpy="0.0 0.0 0.0" xyz="0.0 0.0 -0.050"/>
    </collision>
    <inertial>
      <mass value="0.1"/>
      <inertia ixx="1000" ixy="0" ixz="0" iyy="1000" iyz="0" izz="1000"/>
    </inertial>
  </link>
  <link name="FR_toe_link">
    <visual>
      <geometry>
        <mesh filename="package://spotmicro_description/urdf/stl/foot.stl" scale="0.001 0.001 0.001"/>
      </geometry>
      <origin rpy="0 -0.40010 3.14159" xyz="0.00 0.01 0.015"/>
      <material name="black"/>
    </visual>
    <collision>
      <geometry>
        <sphere radius="0.02"/>
      </geometry>
      <origin rpy="0 0 0" xyz="0 0 0.02"/>
      <contact_coefficients mu="1.1"/>
    </collision>
    <inertial>
      <mass value="0.05"/>
      <inertia ixx="1000" ixy="0" ixz="0" iyy="1000" iyz="0" izz="1000"/>
    </inertial>
  </link>
  <joint name="FR_Coxa" type="revolute">
    <parent link="base_link"/>
    <child link="FR_coxa_link"/>
    <axis xyz="1 0 0"/>
    <origin rpy="0 0 0" xyz="0.093 -0.039 0"/>
    <limit effort="1000.0" lower="-0.548" upper="0.548" velocity="0.7"/>
    <dynamics damping="0.0" friction="0.5"/>
  </joint>
  <joint name="FR_Femur" type="revolute">
    <parent link="FR_coxa_link"/>
    <child link="FR_femur_link"/>
    <axis xyz="0 1 0"/>
    <origin rpy="0 1.4308 0" xyz="0 -0.055 0"/>
    <limit effort="1000.0" lower="-1.5708" upper="0.523599" velocity="0.5"/>
    <dynamics damping="0.0" friction="0.0"/>
  </joint>
  <joint name="FR_femur_cover_joint" type="fixed">
    <parent link="FR_femur_link"/>
    <child link="FR_femur_link_cover"/>
    <origin xyz="0 0 0"/>
  </joint>
  <joint name="FR_Tibia" type="revolute">
    <parent link="FR_femur_link"/>
    <child link="FR_tibia_link"/>
    <axis xyz="0 1 0"/>
    <origin rpy="0 3.28159 0" xyz="0 0 -0.1075"/>
    <limit effort="1000.0" lower="0" upper="3.14159" velocity="0.5"/>
    <dynamics damping="0.0" friction="0.5"/>
  </joint>
  <joint name="FR_toe" type="fixed">
    <parent link="FR_tibia_link"/>
    <child link="FR_toe_link"/>
    <origin xyz="0 0 -0.13"/>
  </joint>
  <link name="BL_coxa_link">
    <visual>
      <geometry>
        <mesh filename="package://spotmicro_description/urdf/stl/lshoulder.stl" scale="0.001 0.001 0.001"/>
      </geometry>
      <origin rpy="0 0 3.14159" xyz="0.135 0.015 -0.01"/>
      <material name="black"/>
    </visual>
    <collision>
      <geometry>
        <box size="0.044 0.038 0.07"/>
      </geometry>
      <origin rpy="0 0 0" xyz="0 0 0"/>
    </collision>
    <inertial>
      <mass value="0.10"/>
      <inertia ixx="100" ixy="0" ixz="0" iyy="100" iyz="0" izz="100"/>
    </inertial>
  </link>
  <link name="BL_femur_link_cover">
    <visual>
      <geometry>
        <mesh filename="package://spotmicro_description/urdf/stl/larm_cover.stl" scale="0.001 0.001 0.001"/>
      </geometry>
      <origin rpy="0 -0.139 3.14159" xyz="0.130 -0.040 -0.025"/>
      <material name="black"/>
    </visual>
  </link>
  <link name="BL_femur_link">
    <visual>
      <geometry>
        <mesh filename="package://spotmicro_description/urdf/stl/larm.stl" scale="0.001 0.001 0.001"/>
      </geometry>
      <origin rpy="0 -0.139 3.14159" xyz="0.130 -0.040 -0.025"/>
      <material name="black"/>
      <!--        <geometry>
          <box size="0.028 0.036 ${femur_length}"/>
        </geometry>
        <origin rpy="0.0 0.0 0.0" xyz="0.0 0.0 -0.050"/>
        <material name="black"/>-->
    </visual>
    <collision>
      <origin rpy="0.0 0.0 0.0" xyz="0.0 0.0 -0.050"/>
      <geometry>
        <box size="0.028 0.036 0.1075"/>
      </geometry>
    </collision>
    <inertial>
      <mass value="0.15"/>
      <inertia ixx="1000" ixy="0" ixz="0" iyy="1000" iyz="0" izz="1000"/>
    </inertial>
  </link>
  <link name="BL_tibia_link">
    <visual>
      <geometry>
        <mesh filename="package://spotmicro_description/urdf/stl/lfoot.stl" scale="0.001 0.001 0.001"/>
      </geometry>
      <origin rpy="0 0 3.14159" xyz="0.120 -0.04 0.1"/>
      <material name="black"/>
    </visual>
    <collision>
      <geometry>
        <box size="0.026 0.020 0.13"/>
      </geometry>
      <origin rpy="0.0 0.0 0.0" xyz="0.0 0.0 -0.050"/>
    </collision>
    <inertial>
      <mass value="0.1"/>
      <inertia ixx="1000" ixy="0" ixz="0" iyy="1000" iyz="0" izz="1000"/>
    </inertial>
  </link>
  <link name="BL_toe_link">
    <visual>
      <geometry>
        <mesh filename="package://spotmicro_description/urdf/stl/foot.stl" scale="0.001 0.001 0.001"/>
      </geometry>
      <origin rpy="0 -0.40010 3.14159" xyz="0.00 0.01 0.015"/>
      <material name="black"/>
    </visual>
    <collision>
      <geometry>
        <sphere radius="0.02"/>
      </geometry>
      <origin rpy="0 0 0" xyz="0 0 0.02"/>
      <contact_coefficients mu="1.1"/>
    </collision>
    <inertial>
      <mass value="0.05"/>
      <inertia ixx="1000" ixy="0" ixz="0" iyy="1000" iyz="0" izz="1000"/>
    </inertial>
  </link>
  <joint name="BL_Coxa" type="revolute">
    <parent link="base_link"/>
    <child link="BL_coxa_link"/>
    <axis xyz="1 0 0"/>
    <origin rpy="0 0 0" xyz="-0.093 0.039 0"/>
    <limit effort="1000.0" lower="-0.548" upper="0.548" velocity="0.7"/>
    <dynamics damping="0.0" friction="0.5"/>
  </joint>
  <joint name="BL_Femur" type="revolute">
    <parent link="BL_coxa_link"/>
    <child link="BL_femur_link"/>
    <axis xyz="0 1 0"/>
    <origin rpy="0 1.4308 0" xyz="0 0.055 0"/>
    <limit effort="1000.0" lower="-1.5708" upper="0.523599" velocity="0.5"/>
    <dynamics damping="0.0" friction="0.0"/>
  </joint>
  <joint name="BL_femur_cover_joint" type="fixed">
    <parent link="BL_femur_link"/>
    <child link="BL_femur_link_cover"/>
    <origin xyz="0 0 0"/>
  </joint>
  <joint name="BL_Tibia" type="revolute">
    <parent link="BL_femur_link"/>
    <child link="BL_tibia_link"/>
    <axis xyz="0 1 0"/>
    <origin rpy="0 3.28159 0" xyz="0 0 -0.1075"/>
    <limit effort="1000.0" lower="0" upper="3.14159" velocity="0.5"/>
    <dynamics damping="0.0" friction="0.5"/>
  </joint>
  <joint name="BL_toe" type="fixed">
    <parent link="BL_tibia_link"/>
    <child link="BL_toe_link"/>
    <origin xyz="0 0 -0.13"/>
  </joint>
  <link name="BR_coxa_link">
    <visual>
      <geometry>
        <mesh filename="package://spotmicro_description/urdf/stl/rshoulder.stl" scale="0.001 0.001 0.001"/>
      </geometry>
      <origin rpy="0 0 3.14159" xyz="0.135 0.095 -0.01"/>
      <material name="black"/>
    </visual>
    <collision>
      <geometry>
        <box size="0.044 0.038 0.07"/>
      </geometry>
      <origin rpy="0 0 0" xyz="0 0 0"/>
    </collision>
    <inertial>
      <mass value="0.10"/>
      <inertia ixx="100" ixy="0" ixz="0" iyy="100" iyz="0" izz="100"/>
    </inertial>
  </link>
  <link name="BR_femur_link_cover">
    <visual>
      <geometry>
        <mesh filename="package://spotmicro_description/urdf/stl/rarm_cover.stl" scale="0.001 0.001 0.001"/>
      </geometry>
      <origin rpy="0 -0.139 3.14159" xyz="0.130 0.15 -0.025"/>
      <material name="black"/>
    </visual>
  </link>
  <link name="BR_femur_link">
    <visual>
      <geometry>
        <mesh filename="package://spotmicro_description/urdf/stl/rarm.stl" scale="0.001 0.001 0.001"/>
      </geometry>
      <origin rpy="0 -0.139 3.14159" xyz="0.130 0.15 -0.025"/>
      <material name="black"/>
      <!--        <geometry>
          <box size="0.028 0.036 ${femur_length}"/>
        </geometry>
        <origin rpy="0.0 0.0 0.0" xyz="0.0 0.0 -0.050"/>
        <material name="black"/>-->
    </visual>
    <collision>
      <origin rpy="0.0 0.0 0.0" xyz="0.0 0.0 -0.050"/>
      <geometry>
        <box size="0.028 0.036 0.1075"/>
      </geometry>
    </collision>
    <inertial>
      <mass value="0.15"/>
      <inertia ixx="1000" ixy="0" ixz="0" iyy="1000" iyz="0" izz="1000"/>
    </inertial>
  </link>
  <link name="BR_tibia_link">
    <visual>
      <geometry>
        <mesh filename="package://spotmicro_description/urdf/stl/rfoot.stl" scale="0.001 0.001 0.001"/>
      </geometry>
      <origin rpy="0 0 3.14159" xyz="0.120 0.15 0.1"/>
      <material name="black"/>
    </visual>
    <collision>
      <geometry>
        <box size="0.026 0.020 0.13"/>
      </geometry>
      <origin rpy="0.0 0.0 0.0" xyz="0.0 0.0 -0.050"/>
    </collision>
    <inertial>
      <mass value="0.1"/>
      <inertia ixx="1000" ixy="0" ixz="0" iyy="1000" iyz="0" izz="1000"/>
    </inertial>
  </link>
  <link name="BR_toe_link">
    <visual>
      <geometry>
        <mesh filename="package://spotmicro_description/urdf/stl/foot.stl" scale="0.001 0.001 0.001"/>
      </geometry>
      <origin rpy="0 -0.40010 3.14159" xyz="0.00 0.01 0.015"/>
      <material name="black"/>
    </visual>
    <collision>
      <geometry>
        <sphere radius="0.02"/>
      </geometry>
      <origin rpy="0 0 0" xyz="0 0 0.02"/>
      <contact_coefficients mu="1.1"/>
    </collision>
    <inertial>
      <mass value="0.05"/>
      <inertia ixx="1000" ixy="0" ixz="0" iyy="1000" iyz="0" izz="1000"/>
    </inertial>
  </link>
  <joint name="BR_Coxa" type="revolute">
    <parent link="base_link"/>
    <child link="BR_coxa_link"/>
    <axis xyz="1 0 0"/>
    <origin rpy="0 0 0" xyz="-0.093 -0.039 0"/>
    <limit effort="1000.0" lower="-0.548" upper="0.548" velocity="0.7"/>
    <dynamics damping="0.0" friction="0.5"/>
  </joint>
  <joint name="BR_Femur" type="revolute">
    <parent link="BR_coxa_link"/>
    <child link="BR_femur_link"/>
    <axis xyz="0 1 0"/>
    <origin rpy="0 1.4308 0" xyz="0 -0.055 0"/>
    <limit effort="1000.0" lower="-1.5708" upper="0.523599" velocity="0.5"/>
    <dynamics damping="0.0" friction="0.0"/>
  </joint>
  <joint name="BR_femur_cover_joint" type="fixed">
    <parent link="BR_femur_link"/>
    <child link="BR_femur_link_cover"/>
    <origin xyz="0 0 0"/>
  </joint>
  <joint name="BR_Tibia" type="revolute">
    <parent link="BR_femur_link"/>
    <child link="BR_tibia_link"/>
    <axis xyz="0 1 0"/>
    <origin rpy="0 3.28159 0" xyz="0 0 -0.1075"/>
    <limit effort="1000.0" lower="0" upper="3.14159" velocity="0.5"/>
    <dynamics damping="0.0" friction="0.5"/>
  </joint>
  <joint name="BR_toe" type="fixed">
    <parent link="BR_tibia_link"/>
    <child link="BR_toe_link"/>
    <origin xyz="0 0 -0.13"/>
  </joint>
</robot>

